Workbook
Name Slicer_Site1: #N/A

Sheet Data
A1: Quadrant | B1: Site | C1: metric_std | D1: Date | E1: Performance | F1: intervention | G1: Ideal_Trend | H1: Target | I1: pct_change | J1: Mean | K1: Stdev | L1: Z-SCORE | M1: Z-score FLAG | N1: Distance_from_Target | O1: Prior Interventions | P1: Historical_Outcome | Q1: Decision | R1: intervention_n1 | S1: Decision_Code | T1: New_Intervention | U1: Improvement_Check | V1: Distance_check | W1: z_check | X1: intervention_check | Y1: Improvement_Threshold | Z1: ='Control panel'!AB13 -> 0.01 | AA1: How much improvement is good enough?
A2: Culture | B2: DH | C2: 1st Year Voluntary Turnover | D2: 45535 | E2: 0.304 | F2: 0 | G2: DOWN | H2: 0.27 | I2: 0.017 | J2: =AVERAGEIF($C:$C,C2,$I:$I) -> 0.01250455 | K2: {=_xlfn.STDEV.S(IF($C:$C=C2,$I:$I))} -> 0.053924508 | L2: =IFERROR((I2-J2)/K2,0) -> 0.083365613 | M2: =IF(L2<=-$Z$4,1,IF(L2>=$Z$4,-1,0)) -> 0 | N2: =IFERROR(IF(G2="DOWN",(E2-H2)/H2,(H2-E2)/H2),0) -> 0.12592593 | O2: =COUNTIFS($B$2:B2,B2,$C$2:C2,C2,$D$2:D2,"<"&D2,$F$2:F2,1) -> 0 | P2: =IF(F2=1,IF(I2>=$Z$1,1,-1),0) -> 0 | Q2: =IF(I2>=$Z$1,"Monitor",IF(AND(N2>=$Z$2,L2<=-$Z$4),IF(O2<$Z$3,"Intervene","Escalate / Bigger Fix"),"Monitor")) -> Monitor | R2: 0 | S2: =IF(Q2="Intervene",1,IF(Q2="Escalate / Bigger Fix",-1,0)) -> 0 | T2: =IF(Q2="Intervene",1,0) -> 0 | U2: =IF(I2>=$Z$1,"Improved Enough","Not Improved Enough") -> Improved Enough | V2: =IF(N2>=$Z$2,"Far","Close") -> Far | W2: =IF(L2<=-$Z$4,"Abnormal","Normal") -> Normal | X2: =IF(O2<$Z$3,"Allowed","Maxed Out") -> Allowed | Y2: Distance_Threshold | Z2: ='Control panel'!AB14 -> 0.02 | AA2: How far from target is considered a real problem?”
A3: Culture | B3: DH | C3: 1st Year Voluntary Turnover | D3: 45565 | E3: 0.30009872 | F3: 1 | G3: DOWN | H3: 0.27 | I3: 0.012833169 | J3: =AVERAGEIF($C:$C,C3,$I:$I) -> 0.01250455 | K3: {=_xlfn.STDEV.S(IF($C:$C=C3,$I:$I))} -> 0.053924508 | L3: =IFERROR((I3-J3)/K3,0) -> 0.0060940462 | M3: =IF(L3<=-$Z$4,1,IF(L3>=$Z$4,-1,0)) -> 0 | N3: =IFERROR(IF(G3="DOWN",(E3-H3)/H3,(H3-E3)/H3),0) -> 0.11147673 | O3: =COUNTIFS($B$2:B3,B3,$C$2:C3,C3,$D$2:D3,"<"&D3,$F$2:F3,1) -> 0 | P3: =IF(AND(R3=1,I3>0),1,IF(R3=1,-1,0)) -> 0 | Q3: =IF(I3>=$Z$1,"Monitor",IF(AND(N3>=$Z$2,L3<=-$Z$4),IF(O3<$Z$3,"Intervene","Escalate / Bigger Fix"),"Monitor")) -> Monitor | R3: 0 | S3: =IF(Q3="Intervene",1,IF(Q3="Escalate / Bigger Fix",-1,0)) -> 0 | T3: =IF(Q3="Intervene",1,0) -> 0 | U3: =IF(I3>=$Z$1,"Improved Enough","Not Improved Enough") -> Improved Enough | V3: =IF(N3>=$Z$2,"Far","Close") -> Far | W3: =IF(L3<=-$Z$4,"Abnormal","Normal") -> Normal | X3: =IF(O3<$Z$3,"Allowed","Maxed Out") -> Allowed | Y3: Max_Prior_Interventions | Z3: ='Control panel'!AB15 -> 5 | AA3: How many times can we try before giving up?
A4: Culture | B4: DH | C4: 1st Year Voluntary Turnover | D4: 45596 | E4: 0.29296875 | F4: 0 | G4: DOWN | H4: 0.27 | I4: 0.023758738 | J4: =AVERAGEIF($C:$C,C4,$I:$I) -> 0.01250455 | K4: {=_xlfn.STDEV.S(IF($C:$C=C4,$I:$I))} -> 0.053924508 | L4: =IFERROR((I4-J4)/K4,0) -> 0.20870264 | M4: =IF(L4<=-$Z$4,1,IF(L4>=$Z$4,-1,0)) -> 0 | N4: =IFERROR(IF(G4="DOWN",(E4-H4)/H4,(H4-E4)/H4),0) -> 0.085069444 | O4: =COUNTIFS($B$2:B4,B4,$C$2:C4,C4,$D$2:D4,"<"&D4,$F$2:F4,1) -> 1 | P4: =IF(AND(R4=1,I4>0),1,IF(R4=1,-1,0)) -> 1 | Q4: =IF(I4>=$Z$1,"Monitor",IF(AND(N4>=$Z$2,L4<=-$Z$4),IF(O4<$Z$3,"Intervene","Escalate / Bigger Fix"),"Monitor")) -> Monitor | R4: 1 | S4: =IF(Q4="Intervene",1,IF(Q4="Escalate / Bigger Fix",-1,0)) -> 0 | T4: =IF(Q4="Intervene",1,0) -> 0 | U4: =IF(I4>=$Z$1,"Improved Enough","Not Improved Enough") -> Improved Enough | V4: =IF(N4>=$Z$2,"Far","Close") -> Far | W4: =IF(L4<=-$Z$4,"Abnormal","Normal") -> Normal | X4: =IF(O4<$Z$3,"Allowed","Maxed Out") -> Allowed | Y4: Z Threshold | Z4: ='Control panel'!AB16 -> 0.5 | AA4: How sensitive should we be to unusual changes?
A5: Culture | B5: DH | C5: 1st Year Voluntary Turnover | D5: 45626 | E5: 0.29088559 | F5: 0 | G5: DOWN | H5: 0.27 | I5: 0.0071105365 | J5: =AVERAGEIF($C:$C,C5,$I:$I) -> 0.01250455 | K5: {=_xlfn.STDEV.S(IF($C:$C=C5,$I:$I))} -> 0.053924508 | L5: =IFERROR((I5-J5)/K5,0) -> -0.10002899 | M5: =IF(L5<=-$Z$4,1,IF(L5>=$Z$4,-1,0)) -> 0 | N5: =IFERROR(IF(G5="DOWN",(E5-H5)/H5,(H5-E5)/H5),0) -> 0.077354019 | O5: =COUNTIFS($B$2:B5,B5,$C$2:C5,C5,$D$2:D5,"<"&D5,$F$2:F5,1) -> 1 | P5: =IF(AND(R5=1,I5>0),1,IF(R5=1,-1,0)) -> 0 | Q5: =IF(I5>=$Z$1,"Monitor",IF(AND(N5>=$Z$2,L5<=-$Z$4),IF(O5<$Z$3,"Intervene","Escalate / Bigger Fix"),"Monitor")) -> Monitor | R5: 0 | S5: =IF(Q5="Intervene",1,IF(Q5="Escalate / Bigger Fix",-1,0)) -> 0 | T5: =IF(Q5="Intervene",1,0) -> 0 | U5: =IF(I5>=$Z$1,"Improved Enough","Not Improved Enough") -> Not Improved Enough | V5: =IF(N5>=$Z$2,"Far","Close") -> Far | W5: =IF(L5<=-$Z$4,"Abnormal","Normal") -> Normal | X5: =IF(O5<$Z$3,"Allowed","Maxed Out") -> Allowed
A6: Culture | B6: DH | C6: 1st Year Voluntary Turnover | D6: 45657 | E6: 0.30193548 | F6: 1 | G6: DOWN | H6: 0.27 | I6: -0.037987097 | J6: =AVERAGEIF($C:$C,C6,$I:$I) -> 0.01250455 | K6: {=_xlfn.STDEV.S(IF($C:$C=C6,$I:$I))} -> 0.053924508 | L6: =IFERROR((I6-J6)/K6,0) -> -0.93633951 | M6: =IF(L6<=-$Z$4,1,IF(L6>=$Z$4,-1,0)) -> 1 | N6: =IFERROR(IF(G6="DOWN",(E6-H6)/H6,(H6-E6)/H6),0) -> 0.11827957 | O6: =COUNTIFS($B$2:B6,B6,$C$2:C6,C6,$D$2:D6,"<"&D6,$F$2:F6,1) -> 1 | P6: =IF(AND(R6=1,I6>0),1,IF(R6=1,-1,0)) -> 0 | Q6: =IF(I6>=$Z$1,"Monitor",IF(AND(N6>=$Z$2,L6<=-$Z$4),IF(O6<$Z$3,"Intervene","Escalate / Bigger Fix"),"Monitor")) -> Intervene | R6: 0 | S6: =IF(Q6="Intervene",1,IF(Q6="Escalate / Bigger Fix",-1,0)) -> 1 | T6: =IF(Q6="Intervene",1,0) -> 1 | U6: =IF(I6>=$Z$1,"Improved Enough","Not Improved Enough") -> Not Improved Enough | V6: =IF(N6>=$Z$2,"Far","Close") -> Far | W6: =IF(L6<=-$Z$4,"Abnormal","Normal") -> Abnormal | X6: =IF(O6<$Z$3,"Allowed","Maxed Out") -> Allowed
A7: Culture | B7: DH | C7: 1st Year Voluntary Turnover | D7: 45688 | E7: 0.30232558 | F7: 1 | G7: DOWN | H7: 0.27 | I7: -0.0012919897 | J7: =AVERAGEIF($C:$C,C7,$I:$I) -> 0.01250455 | K7: {=_xlfn.STDEV.S(IF($C:$C=C7,$I:$I))} -> 0.053924508 | L7: =IFERROR((I7-J7)/K7,0) -> -0.25584916 | M7: =IF(L7<=-$Z$4,1,IF(L7>=$Z$4,-1,0)) -> 0 | N7: =IFERROR(IF(G7="DOWN",(E7-H7)/H7,(H7-E7)/H7),0) -> 0.11972438 | O7: =COUNTIFS($B$2:B7,B7,$C$2:C7,C7,$D$2:D7,"<"&D7,$F$2:F7,1) -> 2 | P7: =IF(AND(R7=1,I7>0),1,IF(R7=1,-1,0)) -> -1 | Q7: =IF(I7>=$Z$1,"Monitor",IF(AND(N7>=$Z$2,L7<=-$Z$4),IF(O7<$Z$3,"Intervene","Escalate / Bigger Fix"),"Monitor")) -> Monitor | R7: 1 | S7: =IF(Q7="Intervene",1,IF(Q7="Escalate / Bigger Fix",-1,0)) -> 0 | T7: =IF(Q7="Intervene",1,0) -> 0 | U7: =IF(I7>=$Z$1,"Improved Enough","Not Improved Enough") -> Not Improved Enough | V7: =IF(N7>=$Z$2,"Far","Close") -> Far | W7: =IF(L7<=-$Z$4,"Abnormal","Normal") -> Normal | X7: =IF(O7<$Z$3,"Allowed","Maxed Out") -> Allowed
A8: Culture | B8: DH | C8: 1st Year Voluntary Turnover | D8: 45716 | E8: 0.28859279 | F8: 0 | G8: DOWN | H8: 0.27 | I8: 0.045423864 | J8: =AVERAGEIF($C:$C,C8,$I:$I) -> 0.01250455 | K8: {=_xlfn.STDEV.S(IF($C:$C=C8,$I:$I))} -> 0.053924508 | L8: =IFERROR((I8-J8)/K8,0) -> 0.61047037 | M8: =IF(L8<=-$Z$4,1,IF(L8>=$Z$4,-1,0)) -> -1 | N8: =IFERROR(IF(G8="DOWN",(E8-H8)/H8,(H8-E8)/H8),0) -> 0.068862167 | O8: =COUNTIFS($B$2:B8,B8,$C$2:C8,C8,$D$2:D8,"<"&D8,$F$2:F8,1) -> 3 | P8: =IF(AND(R8=1,I8>0),1,IF(R8=1,-1,0)) -> 1 | Q8: =IF(I8>=$Z$1,"Monitor",IF(AND(N8>=$Z$2,L8<=-$Z$4),IF(O8<$Z$3,"Intervene","Escalate / Bigger Fix"),"Monitor")) -> Monitor | R8: 1 | S8: =IF(Q8="Intervene",1,IF(Q8="Escalate / Bigger Fix",-1,0)) -> 0 | T8: =IF(Q8="Intervene",1,0) -> 0 | U8: =IF(I8>=$Z$1,"Improved Enough","Not Improved Enough") -> Improved Enough | V8: =IF(N8>=$Z$2,"Far","Close") -> Far | W8: =IF(L8<=-$Z$4,"Abnormal","Normal") -> Normal | X8: =IF(O8<$Z$3,"Allowed","Maxed Out") -> Allowed | Z8: Mean | AA8: =AVERAGEIF($C:$C,C2,$I:$I)
A9: Culture | B9: DH | C9: 1st Year Voluntary Turnover | D9: 45747 | E9: 0.27227886 | F9: 0 | G9: DOWN | H9: 0.27 | I9: 0.056529236 | J9: =AVERAGEIF($C:$C,C9,$I:$I) -> 0.01250455 | K9: {=_xlfn.STDEV.S(IF($C:$C=C9,$I:$I))} -> 0.053924508 | L9: =IFERROR((I9-J9)/K9,0) -> 0.8164133 | M9: =IF(L9<=-$Z$4,1,IF(L9>=$Z$4,-1,0)) -> -1 | N9: =IFERROR(IF(G9="DOWN",(E9-H9)/H9,(H9-E9)/H9),0) -> 0.0084402061 | O9: =COUNTIFS($B$2:B9,B9,$C$2:C9,C9,$D$2:D9,"<"&D9,$F$2:F9,1) -> 3 | P9: =IF(AND(R9=1,I9>0),1,IF(R9=1,-1,0)) -> 0 | Q9: =IF(I9>=$Z$1,"Monitor",IF(AND(N9>=$Z$2,L9<=-$Z$4),IF(O9<$Z$3,"Intervene","Escalate / Bigger Fix"),"Monitor")) -> Monitor | R9: 0 | S9: =IF(Q9="Intervene",1,IF(Q9="Escalate / Bigger Fix",-1,0)) -> 0 | T9: =IF(Q9="Intervene",1,0) -> 0 | U9: =IF(I9>=$Z$1,"Improved Enough","Not Improved Enough") -> Improved Enough | V9: =IF(N9>=$Z$2,"Far","Close") -> Close | W9: =IF(L9<=-$Z$4,"Abnormal","Normal") -> Normal | X9: =IF(O9<$Z$3,"Allowed","Maxed Out") -> Allowed | Z9: Stdev | AA9: =STDEV.S(IF($C:$C=C2,$I:$I))
A10: Culture | B10: DH | C10: 1st Year Voluntary Turnover | D10: 45777 | E10: 0.25540541 | F10: 0 | G10: DOWN | H10: 0.27 | I10: 0.06197121 | J10: =AVERAGEIF($C:$C,C10,$I:$I) -> 0.01250455 | K10: {=_xlfn.STDEV.S(IF($C:$C=C10,$I:$I))} -> 0.053924508 | L10: =IFERROR((I10-J10)/K10,0) -> 0.91733169 | M10: =IF(L10<=-$Z$4,1,IF(L10>=$Z$4,-1,0)) -> -1 | N10: =IFERROR(IF(G10="DOWN",(E10-H10)/H10,(H10-E10)/H10),0) -> -0.054054054 | O10: =COUNTIFS($B$2:B10,B10,$C$2:C10,C10,$D$2:D10,"<"&D10,$F$2:F10,1) -> 3 | P10: =IF(AND(R10=1,I10>0),1,IF(R10=1,-1,0)) -> 0 | Q10: =IF(I10>=$Z$1,"Monitor",IF(AND(N10>=$Z$2,L10<=-$Z$4),IF(O10<$Z$3,"Intervene","Escalate / Bigger Fix"),"Monitor")) -> Monitor | R10: 0 | S10: =IF(Q10="Intervene",1,IF(Q10="Escalate / Bigger Fix",-1,0)) -> 0 | T10: =IF(Q10="Intervene",1,0) -> 0 | U10: =IF(I10>=$Z$1,"Improved Enough","Not Improved Enough") -> Improved Enough | V10: =IF(N10>=$Z$2,"Far","Close") -> Close | W10: =IF(L10<=-$Z$4,"Abnormal","Normal") -> Normal | X10: =IF(O10<$Z$3,"Allowed","Maxed Out") -> Allowed | Z10: Z-SCORE | AA10: =IFERROR((I2-J2)/K2,0)
A11: Culture | B11: DH | C11: 1st Year Voluntary Turnover | D11: 45808 | E11: 0.25311203 | F11: 0 | G11: DOWN | H11: 0.27 | I11: 0.0089793409 | J11: =AVERAGEIF($C:$C,C11,$I:$I) -> 0.01250455 | K11: {=_xlfn.STDEV.S(IF($C:$C=C11,$I:$I))} -> 0.053924508 | L11: =IFERROR((I11-J11)/K11,0) -> -0.065373048 | M11: =IF(L11<=-$Z$4,1,IF(L11>=$Z$4,-1,0)) -> 0 | N11: =IFERROR(IF(G11="DOWN",(E11-H11)/H11,(H11-E11)/H11),0) -> -0.062548025 | O11: =COUNTIFS($B$2:B11,B11,$C$2:C11,C11,$D$2:D11,"<"&D11,$F$2:F11,1) -> 3 | P11: =IF(AND(R11=1,I11>0),1,IF(R11=1,-1,0)) -> 0 | Q11: =IF(I11>=$Z$1,"Monitor",IF(AND(N11>=$Z$2,L11<=-$Z$4),IF(O11<$Z$3,"Intervene","Escalate / Bigger Fix"),"Monitor")) -> Monitor | R11: 0 | S11: =IF(Q11="Intervene",1,IF(Q11="Escalate / Bigger Fix",-1,0)) -> 0 | T11: =IF(Q11="Intervene",1,0) -> 0 | U11: =IF(I11>=$Z$1,"Improved Enough","Not Improved Enough") -> Not Improved Enough | V11: =IF(N11>=$Z$2,"Far","Close") -> Close | W11: =IF(L11<=-$Z$4,"Abnormal","Normal") -> Normal | X11: =IF(O11<$Z$3,"Allowed","Maxed Out") -> Allowed | Z11: Z-score FLAG | AA11: =IF(L2<=-$Z$4,1,IF(L2>=$Z$4,-1,0))
A12: Culture | B12: DH | C12: 1st Year Voluntary Turnover | D12: 45838 | E12: 0.24929577 | F12: 0 | G12: DOWN | H12: 0.27 | I12: 0.015077349 | J12: =AVERAGEIF($C:$C,C12,$I:$I) -> 0.01250455 | K12: {=_xlfn.STDEV.S(IF($C:$C=C12,$I:$I))} -> 0.053924508 | L12: =IFERROR((I12-J12)/K12,0) -> 0.047711126 | M12: =IF(L12<=-$Z$4,1,IF(L12>=$Z$4,-1,0)) -> 0 | N12: =IFERROR(IF(G12="DOWN",(E12-H12)/H12,(H12-E12)/H12),0) -> -0.076682316 | O12: =COUNTIFS($B$2:B12,B12,$C$2:C12,C12,$D$2:D12,"<"&D12,$F$2:F12,1) -> 3 | P12: =IF(AND(R12=1,I12>0),1,IF(R12=1,-1,0)) -> 0 | Q12: =IF(I12>=$Z$1,"Monitor",IF(AND(N12>=$Z$2,L12<=-$Z$4),IF(O12<$Z$3,"Intervene","Escalate / Bigger Fix"),"Monitor")) -> Monitor | R12: 0 | S12: =IF(Q12="Intervene",1,IF(Q12="Escalate / Bigger Fix",-1,0)) -> 0 | T12: =IF(Q12="Intervene",1,0) -> 0 | U12: =IF(I12>=$Z$1,"Improved Enough","Not Improved Enough") -> Improved Enough | V12: =IF(N12>=$Z$2,"Far","Close") -> Close | W12: =IF(L12<=-$Z$4,"Abnormal","Normal") -> Normal | X12: =IF(O12<$Z$3,"Allowed","Maxed Out") -> Allowed | Z12: Distance_from_Target | AA12: =IFERROR(IF(G2="DOWN",(E2-H2)/H2,(H2-E2)/H2),0)
A13: Culture | B13: DH | C13: 1st Year Voluntary Turnover | D13: 45869 | E13: 0.24910523 | F13: 0 | G13: DOWN | H13: 0.27 | I13: 0.00076434976 | J13: =AVERAGEIF($C:$C,C13,$I:$I) -> 0.01250455 | K13: {=_xlfn.STDEV.S(IF($C:$C=C13,$I:$I))} -> 0.053924508 | L13: =IFERROR((I13-J13)/K13,0) -> -0.21771549 | M13: =IF(L13<=-$Z$4,1,IF(L13>=$Z$4,-1,0)) -> 0 | N13: =IFERROR(IF(G13="DOWN",(E13-H13)/H13,(H13-E13)/H13),0) -> -0.077388054 | O13: =COUNTIFS($B$2:B13,B13,$C$2:C13,C13,$D$2:D13,"<"&D13,$F$2:F13,1) -> 3 | P13: =IF(AND(R13=1,I13>0),1,IF(R13=1,-1,0)) -> 0 | Q13: =IF(I13>=$Z$1,"Monitor",IF(AND(N13>=$Z$2,L13<=-$Z$4),IF(O13<$Z$3,"Intervene","Escalate / Bigger Fix"),"Monitor")) -> Monitor | R13: 0 | S13: =IF(Q13="Intervene",1,IF(Q13="Escalate / Bigger Fix",-1,0)) -> 0 | T13: =IF(Q13="Intervene",1,0) -> 0 | U13: =IF(I13>=$Z$1,"Improved Enough","Not Improved Enough") -> Not Improved Enough | V13: =IF(N13>=$Z$2,"Far","Close") -> Close | W13: =IF(L13<=-$Z$4,"Abnormal","Normal") -> Normal | X13: =IF(O13<$Z$3,"Allowed","Maxed Out") -> Allowed | Z13: Prior Interventions | AA13: =COUNTIFS($B$2:B2,B2,$C$2:C2,C2,$D$2:D2,"<"&D2,$F$2:F2,1)
A14: Culture | B14: DH | C14: 1st Year Voluntary Turnover | D14: 45900 | E14: 0.24534502 | F14: 0 | G14: DOWN | H14: 0.27 | I14: 0.015094862 | J14: =AVERAGEIF($C:$C,C14,$I:$I) -> 0.01250455 | K14: {=_xlfn.STDEV.S(IF($C:$C=C14,$I:$I))} -> 0.053924508 | L14: =IFERROR((I14-J14)/K14,0) -> 0.048035892 | M14: =IF(L14<=-$Z$4,1,IF(L14>=$Z$4,-1,0)) -> 0 | N14: =IFERROR(IF(G14="DOWN",(E14-H14)/H14,(H14-E14)/H14),0) -> -0.091314754 | O14: =COUNTIFS($B$2:B14,B14,$C$2:C14,C14,$D$2:D14,"<"&D14,$F$2:F14,1) -> 3 | P14: =IF(AND(R14=1,I14>0),1,IF(R14=1,-1,0)) -> 0 | Q14: =IF(I14>=$Z$1,"Monitor",IF(AND(N14>=$Z$2,L14<=-$Z$4),IF(O14<$Z$3,"Intervene","Escalate / Bigger Fix"),"Monitor")) -> Monitor | R14: 0 | S14: =IF(Q14="Intervene",1,IF(Q14="Escalate / Bigger Fix",-1,0)) -> 0 | T14: =IF(Q14="Intervene",1,0) -> 0 | U14: =IF(I14>=$Z$1,"Improved Enough","Not Improved Enough") -> Improved Enough | V14: =IF(N14>=$Z$2,"Far","Close") -> Close | W14: =IF(L14<=-$Z$4,"Abnormal","Normal") -> Normal | X14: =IF(O14<$Z$3,"Allowed","Maxed Out") -> Allowed | Z14: Historical_Outcome | AA14: =IF(F2=1,IF(I2>=$Z$1,1,-1),0)
A15: Culture | B15: DH | C15: 1st Year Voluntary Turnover | D15: 45930 | E15: 0.25484352 | F15: 0 | G15: DOWN | H15: 0.27 | I15: -0.038714871 | J15: =AVERAGEIF($C:$C,C15,$I:$I) -> 0.01250455 | K15: {=_xlfn.STDEV.S(IF($C:$C=C15,$I:$I))} -> 0.053924508 | L15: =IFERROR((I15-J15)/K15,0) -> -0.94983568 | M15: =IF(L15<=-$Z$4,1,IF(L15>=$Z$4,-1,0)) -> 1 | N15: =IFERROR(IF(G15="DOWN",(E15-H15)/H15,(H15-E15)/H15),0) -> -0.056135122 | O15: =COUNTIFS($B$2:B15,B15,$C$2:C15,C15,$D$2:D15,"<"&D15,$F$2:F15,1) -> 3 | P15: =IF(AND(R15=1,I15>0),1,IF(R15=1,-1,0)) -> 0 | Q15: =IF(I15>=$Z$1,"Monitor",IF(AND(N15>=$Z$2,L15<=-$Z$4),IF(O15<$Z$3,"Intervene","Escalate / Bigger Fix"),"Monitor")) -> Monitor | R15: 0 | S15: =IF(Q15="Intervene",1,IF(Q15="Escalate / Bigger Fix",-1,0)) -> 0 | T15: =IF(Q15="Intervene",1,0) -> 0 | U15: =IF(I15>=$Z$1,"Improved Enough","Not Improved Enough") -> Not Improved Enough | V15: =IF(N15>=$Z$2,"Far","Close") -> Close | W15: =IF(L15<=-$Z$4,"Abnormal","Normal") -> Abnormal | X15: =IF(O15<$Z$3,"Allowed","Maxed Out") -> Allowed | Z15: Decision | AA15: =IF(I2>=$Z$1,"Monitor",IF(AND(N2>=$Z$2,L2<=-$Z$4),IF(O2<$Z$3,"Intervene","Escalate / Bigger Fix"),"Monitor"))
A16: Culture | B16: DH | C16: 1st Year Voluntary Turnover | D16: 45961 | E16: 0.2519084 | F16: 0 | G16: DOWN | H16: 0.27 | I16: 0.011517343 | J16: =AVERAGEIF($C:$C,C16,$I:$I) -> 0.01250455 | K16: {=_xlfn.STDEV.S(IF($C:$C=C16,$I:$I))} -> 0.053924508 | L16: =IFERROR((I16-J16)/K16,0) -> -0.018307212 | M16: =IF(L16<=-$Z$4,1,IF(L16>=$Z$4,-1,0)) -> 0 | N16: =IFERROR(IF(G16="DOWN",(E16-H16)/H16,(H16-E16)/H16),0) -> -0.067005937 | O16: =COUNTIFS($B$2:B16,B16,$C$2:C16,C16,$D$2:D16,"<"&D16,$F$2:F16,1) -> 3 | P16: =IF(AND(R16=1,I16>0),1,IF(R16=1,-1,0)) -> 0 | Q16: =IF(I16>=$Z$1,"Monitor",IF(AND(N16>=$Z$2,L16<=-$Z$4),IF(O16<$Z$3,"Intervene","Escalate / Bigger Fix"),"Monitor")) -> Monitor | R16: 0 | S16: =IF(Q16="Intervene",1,IF(Q16="Escalate / Bigger Fix",-1,0)) -> 0 | T16: =IF(Q16="Intervene",1,0) -> 0 | U16: =IF(I16>=$Z$1,"Improved Enough","Not Improved Enough") -> Improved Enough | V16: =IF(N16>=$Z$2,"Far","Close") -> Close | W16: =IF(L16<=-$Z$4,"Abnormal","Normal") -> Normal | X16: =IF(O16<$Z$3,"Allowed","Maxed Out") -> Allowed | Z16: Decision_Code | AA16: =IF(Q2="Intervene",1,IF(Q2="Escalate / Bigger Fix",-1,0))
A17: Culture | B17: DH | C17: 1st Year Voluntary Turnover | D17: 45991 | E17: 0.24394058 | F17: 0 | G17: DOWN | H17: 0.27 | I17: 0.031629824 | J17: =AVERAGEIF($C:$C,C17,$I:$I) -> 0.01250455 | K17: {=_xlfn.STDEV.S(IF($C:$C=C17,$I:$I))} -> 0.053924508 | L17: =IFERROR((I17-J17)/K17,0) -> 0.35466757 | M17: =IF(L17<=-$Z$4,1,IF(L17>=$Z$4,-1,0)) -> 0 | N17: =IFERROR(IF(G17="DOWN",(E17-H17)/H17,(H17-E17)/H17),0) -> -0.096516376 | O17: =COUNTIFS($B$2:B17,B17,$C$2:C17,C17,$D$2:D17,"<"&D17,$F$2:F17,1) -> 3 | P17: =IF(AND(R17=1,I17>0),1,IF(R17=1,-1,0)) -> 0 | Q17: =IF(I17>=$Z$1,"Monitor",IF(AND(N17>=$Z$2,L17<=-$Z$4),IF(O17<$Z$3,"Intervene","Escalate / Bigger Fix"),"Monitor")) -> Monitor | R17: 0 | S17: =IF(Q17="Intervene",1,IF(Q17="Escalate / Bigger Fix",-1,0)) -> 0 | T17: =IF(Q17="Intervene",1,0) -> 0 | U17: =IF(I17>=$Z$1,"Improved Enough","Not Improved Enough") -> Improved Enough | V17: =IF(N17>=$Z$2,"Far","Close") -> Close | W17: =IF(L17<=-$Z$4,"Abnormal","Normal") -> Normal | X17: =IF(O17<$Z$3,"Allowed","Maxed Out") -> Allowed | Z17: New_Intervention | AA17: =IF(Q2="Intervene",1,0)
A18: Culture | B18: DH | C18: AES Metric 1 | D18: 45535 | E18: 0.078461538 | F18: 0 | G18: DOWN | H18: 0.054 | I18: 0.058461538 | J18: =AVERAGEIF($C:$C,C18,$I:$I) -> 0.010109679 | K18: {=_xlfn.STDEV.S(IF($C:$C=C18,$I:$I))} -> 0.17556417 | L18: =IFERROR((I18-J18)/K18,0) -> 0.27540848 | M18: =IF(L18<=-$Z$4,1,IF(L18>=$Z$4,-1,0)) -> 0 | N18: =IFERROR(IF(G18="DOWN",(E18-H18)/H18,(H18-E18)/H18),0) -> 0.45299145 | O18: =COUNTIFS($B$2:B18,B18,$C$2:C18,C18,$D$2:D18,"<"&D18,$F$2:F18,1) -> 0 | P18: =IF(AND(R18=1,I18>0),1,IF(R18=1,-1,0)) -> 0 | Q18: =IF(I18>=$Z$1,"Monitor",IF(AND(N18>=$Z$2,L18<=-$Z$4),IF(O18<$Z$3,"Intervene","Escalate / Bigger Fix"),"Monitor")) -> Monitor | R18: 0 | S18: =IF(Q18="Intervene",1,IF(Q18="Escalate / Bigger Fix",-1,0)) -> 0 | T18: =IF(Q18="Intervene",1,0) -> 0 | U18: =IF(I18>=$Z$1,"Improved Enough","Not Improved Enough") -> Improved Enough | V18: =IF(N18>=$Z$2,"Far","Close") -> Far | W18: =IF(L18<=-$Z$4,"Abnormal","Normal") -> Normal | X18: =IF(O18<$Z$3,"Allowed","Maxed Out") -> Allowed | Z18: Improvement_Check | AA18: =IF(I2>=$Z$1,"Improved Enough","Not Improved Enough")
A19: Culture | B19: DH | C19: AES Metric 1 | D19: 45565 | E19: 0.069821567 | F19: 0 | G19: DOWN | H19: 0.054 | I19: 0.11011728 | J19: =AVERAGEIF($C:$C,C19,$I:$I) -> 0.010109679 | K19: {=_xlfn.STDEV.S(IF($C:$C=C19,$I:$I))} -> 0.17556417 | L19: =IFERROR((I19-J19)/K19,0) -> 0.56963562 | M19: =IF(L19<=-$Z$4,1,IF(L19>=$Z$4,-1,0)) -> -1 | N19: =IFERROR(IF(G19="DOWN",(E19-H19)/H19,(H19-E19)/H19),0) -> 0.29299198 | O19: =COUNTIFS($B$2:B19,B19,$C$2:C19,C19,$D$2:D19,"<"&D19,$F$2:F19,1) -> 0 | P19: =IF(AND(R19=1,I19>0),1,IF(R19=1,-1,0)) -> 0 | Q19: =IF(I19>=$Z$1,"Monitor",IF(AND(N19>=$Z$2,L19<=-$Z$4),IF(O19<$Z$3,"Intervene","Escalate / Bigger Fix"),"Monitor")) -> Monitor | R19: 0 | S19: =IF(Q19="Intervene",1,IF(Q19="Escalate / Bigger Fix",-1,0)) -> 0 | T19: =IF(Q19="Intervene",1,0) -> 0 | U19: =IF(I19>=$Z$1,"Improved Enough","Not Improved Enough") -> Improved Enough | V19: =IF(N19>=$Z$2,"Far","Close") -> Far | W19: =IF(L19<=-$Z$4,"Abnormal","Normal") -> Normal | X19: =IF(O19<$Z$3,"Allowed","Maxed Out") -> Allowed | Z19: Distance_check | AA19: =IF(N2>=$Z$2,"Far","Close")
... A21: Culture | B21: DH | C21: AES Metric 1 | D21: 45626 | E21: 0.064414768 | F21: 0 | G21: DOWN | H21: 0.054 | I21: 0.097485393 | J21: =AVERAGEIF($C:$C,C21,$I:$I) -> 0.010109679 | K21: {=_xlfn.STDEV.S(IF($C:$C=C21,$I:$I))} -> 0.17556417 | L21: =IFERROR((I21-J21)/K21,0) -> 0.49768536 | M21: =IF(L21<=-$Z$4,1,IF(L21>=$Z$4,-1,0)) -> 0 | N21: =IFERROR(IF(G21="DOWN",(E21-H21)/H21,(H21-E21)/H21),0) -> 0.19286607 | O21: =COUNTIFS($B$2:B21,B21,$C$2:C21,C21,$D$2:D21,"<"&D21,$F$2:F21,1) -> 0 | P21: =IF(AND(R21=1,I21>0),1,IF(R21=1,-1,0)) -> 0 | Q21: =IF(I21>=$Z$1,"Monitor",IF(AND(N21>=$Z$2,L21<=-$Z$4),IF(O21<$Z$3,"Intervene","Escalate / Bigger Fix"),"Monitor")) -> Monitor | R21: 0 | S21: =IF(Q21="Intervene",1,IF(Q21="Escalate / Bigger Fix",-1,0)) -> 0 | T21: =IF(Q21="Intervene",1,0) -> 0 | U21: =IF(I21>=$Z$1,"Improved Enough","Not Improved Enough") -> Improved Enough | V21: =IF(N21>=$Z$2,"Far","Close") -> Far | W21: =IF(L21<=-$Z$4,"Abnormal","Normal") -> Normal | X21: =IF(O21<$Z$3,"Allowed","Maxed Out") -> Allowed | Z21: intervention_check | AA21: =IF(O2<$Z$3,"Allowed","Maxed Out")
A22: Culture | B22: DH | C22: AES Metric 1 | D22: 45657 | E22: 0.065934066 | F22: 1 | G22: DOWN | H22: 0.054 | I22: -0.023586174 | J22: =AVERAGEIF($C:$C,C22,$I:$I) -> 0.010109679 | K22: {=_xlfn.STDEV.S(IF($C:$C=C22,$I:$I))} -> 0.17556417 | L22: =IFERROR((I22-J22)/K22,0) -> -0.19192899 | M22: =IF(L22<=-$Z$4,1,IF(L22>=$Z$4,-1,0)) -> 0 | N22: =IFERROR(IF(G22="DOWN",(E22-H22)/H22,(H22-E22)/H22),0) -> 0.22100122 | O22: =COUNTIFS($B$2:B22,B22,$C$2:C22,C22,$D$2:D22,"<"&D22,$F$2:F22,1) -> 0 | P22: =IF(AND(R22=1,I22>0),1,IF(R22=1,-1,0)) -> 0 | Q22: =IF(I22>=$Z$1,"Monitor",IF(AND(N22>=$Z$2,L22<=-$Z$4),IF(O22<$Z$3,"Intervene","Escalate / Bigger Fix"),"Monitor")) -> Monitor | R22: 0 | S22: =IF(Q22="Intervene",1,IF(Q22="Escalate / Bigger Fix",-1,0)) -> 0 | T22: =IF(Q22="Intervene",1,0) -> 0 | U22: =IF(I22>=$Z$1,"Improved Enough","Not Improved Enough") -> Not Improved Enough | V22: =IF(N22>=$Z$2,"Far","Close") -> Far | W22: =IF(L22<=-$Z$4,"Abnormal","Normal") -> Normal | X22: =IF(O22<$Z$3,"Allowed","Maxed Out") -> Allowed
A23: Culture | B23: DH | C23: AES Metric 1 | D23: 45688 | E23: 0.073265783 | F23: 1 | G23: DOWN | H23: 0.054 | I23: -0.11119771 | J23: =AVERAGEIF($C:$C,C23,$I:$I) -> 0.010109679 | K23: {=_xlfn.STDEV.S(IF($C:$C=C23,$I:$I))} -> 0.17556417 | L23: =IFERROR((I23-J23)/K23,0) -> -0.69095759 | M23: =IF(L23<=-$Z$4,1,IF(L23>=$Z$4,-1,0)) -> 1 | N23: =IFERROR(IF(G23="DOWN",(E23-H23)/H23,(H23-E23)/H23),0) -> 0.35677377 | O23: =COUNTIFS($B$2:B23,B23,$C$2:C23,C23,$D$2:D23,"<"&D23,$F$2:F23,1) -> 1 | P23: =IF(AND(R23=1,I23>0),1,IF(R23=1,-1,0)) -> -1 | Q23: =IF(I23>=$Z$1,"Monitor",IF(AND(N23>=$Z$2,L23<=-$Z$4),IF(O23<$Z$3,"Intervene","Escalate / Bigger Fix"),"Monitor")) -> Intervene | R23: 1 | S23: =IF(Q23="Intervene",1,IF(Q23="Escalate / Bigger Fix",-1,0)) -> 1 | T23: =IF(Q23="Intervene",1,0) -> 1 | U23: =IF(I23>=$Z$1,"Improved Enough","Not Improved Enough") -> Not Improved Enough | V23: =IF(N23>=$Z$2,"Far","Close") -> Far | W23: =IF(L23<=-$Z$4,"Abnormal","Normal") -> Abnormal | X23: =IF(O23<$Z$3,"Allowed","Maxed Out") -> Allowed
A24: Culture | B24: DH | C24: AES Metric 1 | D24: 45716 | E24: 0.080093313 | F24: 1 | G24: DOWN | H24: 0.054 | I24: -0.093188511 | J24: =AVERAGEIF($C:$C,C24,$I:$I) -> 0.010109679 | K24: {=_xlfn.STDEV.S(IF($C:$C=C24,$I:$I))} -> 0.17556417 | L24: =IFERROR((I24-J24)/K24,0) -> -0.58837855 | M24: =IF(L24<=-$Z$4,1,IF(L24>=$Z$4,-1,0)) -> 1 | N24: =IFERROR(IF(G24="DOWN",(E24-H24)/H24,(H24-E24)/H24),0) -> 0.48320949 | O24: =COUNTIFS($B$2:B24,B24,$C$2:C24,C24,$D$2:D24,"<"&D24,$F$2:F24,1) -> 2 | P24: =IF(AND(R24=1,I24>0),1,IF(R24=1,-1,0)) -> -1 | Q24: =IF(I24>=$Z$1,"Monitor",IF(AND(N24>=$Z$2,L24<=-$Z$4),IF(O24<$Z$3,"Intervene","Escalate / Bigger Fix"),"Monitor")) -> Intervene | R24: 1 | S24: =IF(Q24="Intervene",1,IF(Q24="Escalate / Bigger Fix",-1,0)) -> 1 | T24: =IF(Q24="Intervene",1,0) -> 1 | U24: =IF(I24>=$Z$1,"Improved Enough","Not Improved Enough") -> Not Improved Enough | V24: =IF(N24>=$Z$2,"Far","Close") -> Far | W24: =IF(L24<=-$Z$4,"Abnormal","Normal") -> Abnormal | X24: =IF(O24<$Z$3,"Allowed","Maxed Out") -> Allowed
A25: Culture | B25: DH | C25: AES Metric 1 | D25: 45747 | E25: 0.075617284 | F25: 0 | G25: DOWN | H25: 0.054 | I25: 0.055885173 | J25: =AVERAGEIF($C:$C,C25,$I:$I) -> 0.010109679 | K25: {=_xlfn.STDEV.S(IF($C:$C=C25,$I:$I))} -> 0.17556417 | L25: =IFERROR((I25-J25)/K25,0) -> 0.2607337 | M25: =IF(L25<=-$Z$4,1,IF(L25>=$Z$4,-1,0)) -> 0 | N25: =IFERROR(IF(G25="DOWN",(E25-H25)/H25,(H25-E25)/H25),0) -> 0.40032007 | O25: =COUNTIFS($B$2:B25,B25,$C$2:C25,C25,$D$2:D25,"<"&D25,$F$2:F25,1) -> 3 | P25: =IF(AND(R25=1,I25>0),1,IF(R25=1,-1,0)) -> 1 | Q25: =IF(I25>=$Z$1,"Monitor",IF(AND(N25>=$Z$2,L25<=-$Z$4),IF(O25<$Z$3,"Intervene","Escalate / Bigger Fix"),"Monitor")) -> Monitor | R25: 1 | S25: =IF(Q25="Intervene",1,IF(Q25="Escalate / Bigger Fix",-1,0)) -> 0 | T25: =IF(Q25="Intervene",1,0) -> 0 | U25: =IF(I25>=$Z$1,"Improved Enough","Not Improved Enough") -> Improved Enough | V25: =IF(N25>=$Z$2,"Far","Close") -> Far | W25: =IF(L25<=-$Z$4,"Abnormal","Normal") -> Normal | X25: =IF(O25<$Z$3,"Allowed","Maxed Out") -> Allowed
A26: Culture | B26: DH | C26: AES Metric 1 | D26: 45777 | E26: 0.088703563 | F26: 0 | G26: DOWN | H26: 0.054 | I26: -0.17305937 | J26: =AVERAGEIF($C:$C,C26,$I:$I) -> 0.010109679 | K26: {=_xlfn.STDEV.S(IF($C:$C=C26,$I:$I))} -> 0.17556417 | L26: =IFERROR((I26-J26)/K26,0) -> -1.0433168 | M26: =IF(L26<=-$Z$4,1,IF(L26>=$Z$4,-1,0)) -> 1 | N26: =IFERROR(IF(G26="DOWN",(E26-H26)/H26,(H26-E26)/H26),0) -> 0.64265858 | O26: =COUNTIFS($B$2:B26,B26,$C$2:C26,C26,$D$2:D26,"<"&D26,$F$2:F26,1) -> 3 | P26: =IF(AND(R26=1,I26>0),1,IF(R26=1,-1,0)) -> 0 | Q26: =IF(I26>=$Z$1,"Monitor",IF(AND(N26>=$Z$2,L26<=-$Z$4),IF(O26<$Z$3,"Intervene","Escalate / Bigger Fix"),"Monitor")) -> Intervene | R26: 0 | S26: =IF(Q26="Intervene",1,IF(Q26="Escalate / Bigger Fix",-1,0)) -> 1 | T26: =IF(Q26="Intervene",1,0) -> 1 | U26: =IF(I26>=$Z$1,"Improved Enough","Not Improved Enough") -> Not Improved Enough | V26: =IF(N26>=$Z$2,"Far","Close") -> Far | W26: =IF(L26<=-$Z$4,"Abnormal","Normal") -> Abnormal | X26: =IF(O26<$Z$3,"Allowed","Maxed Out") -> Allowed
A27: Culture | B27: DH | C27: AES Metric 1 | D27: 45808 | E27: 0.086956522 | F27: 0 | G27: DOWN | H27: 0.054 | I27: 0.019695281 | J27: =AVERAGEIF($C:$C,C27,$I:$I) -> 0.010109679 | K27: {=_xlfn.STDEV.S(IF($C:$C=C27,$I:$I))} -> 0.17556417 | L27: =IFERROR((I27-J27)/K27,0) -> 0.054598852 | M27: =IF(L27<=-$Z$4,1,IF(L27>=$Z$4,-1,0)) -> 0 | N27: =IFERROR(IF(G27="DOWN",(E27-H27)/H27,(H27-E27)/H27),0) -> 0.61030596 | O27: =COUNTIFS($B$2:B27,B27,$C$2:C27,C27,$D$2:D27,"<"&D27,$F$2:F27,1) -> 3 | P27: =IF(AND(R27=1,I27>0),1,IF(R27=1,-1,0)) -> 0 | Q27: =IF(I27>=$Z$1,"Monitor",IF(AND(N27>=$Z$2,L27<=-$Z$4),IF(O27<$Z$3,"Intervene","Escalate / Bigger Fix"),"Monitor")) -> Monitor | R27: 0 | S27: =IF(Q27="Intervene",1,IF(Q27="Escalate / Bigger Fix",-1,0)) -> 0 | T27: =IF(Q27="Intervene",1,0) -> 0 | U27: =IF(I27>=$Z$1,"Improved Enough","Not Improved Enough") -> Improved Enough | V27: =IF(N27>=$Z$2,"Far","Close") -> Far | W27: =IF(L27<=-$Z$4,"Abnormal","Normal") -> Normal | X27: =IF(O27<$Z$3,"Allowed","Maxed Out") -> Allowed
A28: Culture | B28: DH | C28: AES Metric 1 | D28: 45838 | E28: 0.075 | F28: 0 | G28: DOWN | H28: 0.054 | I28: 0.1375 | J28: =AVERAGEIF($C:$C,C28,$I:$I) -> 0.010109679 | K28: {=_xlfn.STDEV.S(IF($C:$C=C28,$I:$I))} -> 0.17556417 | L28: =IFERROR((I28-J28)/K28,0) -> 0.72560548 | M28: =IF(L28<=-$Z$4,1,IF(L28>=$Z$4,-1,0)) -> -1 | N28: =IFERROR(IF(G28="DOWN",(E28-H28)/H28,(H28-E28)/H28),0) -> 0.38888889 | O28: =COUNTIFS($B$2:B28,B28,$C$2:C28,C28,$D$2:D28,"<"&D28,$F$2:F28,1) -> 3 | P28: =IF(AND(R28=1,I28>0),1,IF(R28=1,-1,0)) -> 0 | Q28: =IF(I28>=$Z$1,"Monitor",IF(AND(N28>=$Z$2,L28<=-$Z$4),IF(O28<$Z$3,"Intervene","Escalate / Bigger Fix"),"Monitor")) -> Monitor | R28: 0 | S28: =IF(Q28="Intervene",1,IF(Q28="Escalate / Bigger Fix",-1,0)) -> 0 | T28: =IF(Q28="Intervene",1,0) -> 0 | U28: =IF(I28>=$Z$1,"Improved Enough","Not Improved Enough") -> Improved Enough | V28: =IF(N28>=$Z$2,"Far","Close") -> Far | W28: =IF(L28<=-$Z$4,"Abnormal","Normal") -> Normal | X28: =IF(O28<$Z$3,"Allowed","Maxed Out") -> Allowed
A29: Culture | B29: DH | C29: AES Metric 1 | D29: 45869 | E29: 0.06981982 | F29: 0 | G29: DOWN | H29: 0.054 | I29: 0.069069069 | J29: =AVERAGEIF($C:$C,C29,$I:$I) -> 0.010109679 | K29: {=_xlfn.STDEV.S(IF($C:$C=C29,$I:$I))} -> 0.17556417 | L29: =IFERROR((I29-J29)/K29,0) -> 0.33582816 | M29: =IF(L29<=-$Z$4,1,IF(L29>=$Z$4,-1,0)) -> 0 | N29: =IFERROR(IF(G29="DOWN",(E29-H29)/H29,(H29-E29)/H29),0) -> 0.29295963 | O29: =COUNTIFS($B$2:B29,B29,$C$2:C29,C29,$D$2:D29,"<"&D29,$F$2:F29,1) -> 3 | P29: =IF(AND(R29=1,I29>0),1,IF(R29=1,-1,0)) -> 0 | Q29: =IF(I29>=$Z$1,"Monitor",IF(AND(N29>=$Z$2,L29<=-$Z$4),IF(O29<$Z$3,"Intervene","Escalate / Bigger Fix"),"Monitor")) -> Monitor | R29: 0 | S29: =IF(Q29="Intervene",1,IF(Q29="Escalate / Bigger Fix",-1,0)) -> 0 | T29: =IF(Q29="Intervene",1,0) -> 0 | U29: =IF(I29>=$Z$1,"Improved Enough","Not Improved Enough") -> Improved Enough | V29: =IF(N29>=$Z$2,"Far","Close") -> Far | W29: =IF(L29<=-$Z$4,"Abnormal","Normal") -> Normal | X29: =IF(O29<$Z$3,"Allowed","Maxed Out") -> Allowed
A30: Culture | B30: DH | C30: AES Metric 1 | D30: 45900 | E30: 0.067771084 | F30: 0 | G30: DOWN | H30: 0.054 | I30: 0.029343179 | J30: =AVERAGEIF($C:$C,C30,$I:$I) -> 0.010109679 | K30: {=_xlfn.STDEV.S(IF($C:$C=C30,$I:$I))} -> 0.17556417 | L30: =IFERROR((I30-J30)/K30,0) -> 0.10955254 | M30: =IF(L30<=-$Z$4,1,IF(L30>=$Z$4,-1,0)) -> 0 | N30: =IFERROR(IF(G30="DOWN",(E30-H30)/H30,(H30-E30)/H30),0) -> 0.25502008 | O30: =COUNTIFS($B$2:B30,B30,$C$2:C30,C30,$D$2:D30,"<"&D30,$F$2:F30,1) -> 3 | P30: =IF(AND(R30=1,I30>0),1,IF(R30=1,-1,0)) -> 0 | Q30: =IF(I30>=$Z$1,"Monitor",IF(AND(N30>=$Z$2,L30<=-$Z$4),IF(O30<$Z$3,"Intervene","Escalate / Bigger Fix"),"Monitor")) -> Monitor | R30: 0 | S30: =IF(Q30="Intervene",1,IF(Q30="Escalate / Bigger Fix",-1,0)) -> 0 | T30: =IF(Q30="Intervene",1,0) -> 0 | U30: =IF(I30>=$Z$1,"Improved Enough","Not Improved Enough") -> Improved Enough | V30: =IF(N30>=$Z$2,"Far","Close") -> Far | W30: =IF(L30<=-$Z$4,"Abnormal","Normal") -> Normal | X30: =IF(O30<$Z$3,"Allowed","Maxed Out") -> Allowed
A31: Culture | B31: DH | C31: AES Metric 1 | D31: 45930 | E31: 0.062878788 | F31: 0 | G31: DOWN | H31: 0.054 | I31: 0.072188552 | J31: =AVERAGEIF($C:$C,C31,$I:$I) -> 0.010109679 | K31: {=_xlfn.STDEV.S(IF($C:$C=C31,$I:$I))} -> 0.17556417 | L31: =IFERROR((I31-J31)/K31,0) -> 0.35359649 | M31: =IF(L31<=-$Z$4,1,IF(L31>=$Z$4,-1,0)) -> 0 | N31: =IFERROR(IF(G31="DOWN",(E31-H31)/H31,(H31-E31)/H31),0) -> 0.164422 | O31: =COUNTIFS($B$2:B31,B31,$C$2:C31,C31,$D$2:D31,"<"&D31,$F$2:F31,1) -> 3 | P31: =IF(AND(R31=1,I31>0),1,IF(R31=1,-1,0)) -> 0 | Q31: =IF(I31>=$Z$1,"Monitor",IF(AND(N31>=$Z$2,L31<=-$Z$4),IF(O31<$Z$3,"Intervene","Escalate / Bigger Fix"),"Monitor")) -> Monitor | R31: 0 | S31: =IF(Q31="Intervene",1,IF(Q31="Escalate / Bigger Fix",-1,0)) -> 0 | T31: =IF(Q31="Intervene",1,0) -> 0 | U31: =IF(I31>=$Z$1,"Improved Enough","Not Improved Enough") -> Improved Enough | V31: =IF(N31>=$Z$2,"Far","Close") -> Far | W31: =IF(L31<=-$Z$4,"Abnormal","Normal") -> Normal | X31: =IF(O31<$Z$3,"Allowed","Maxed Out") -> Allowed
A32: Culture | B32: DH | C32: AES Metric 1 | D32: 45961 | E32: 0.056445461 | F32: 0 | G32: DOWN | H32: 0.054 | I32: 0.10231314 | J32: =AVERAGEIF($C:$C,C32,$I:$I) -> 0.010109679 | K32: {=_xlfn.STDEV.S(IF($C:$C=C32,$I:$I))} -> 0.17556417 | L32: =IFERROR((I32-J32)/K32,0) -> 0.52518385 | M32: =IF(L32<=-$Z$4,1,IF(L32>=$Z$4,-1,0)) -> -1 | N32: =IFERROR(IF(G32="DOWN",(E32-H32)/H32,(H32-E32)/H32),0) -> 0.045286324 | O32: =COUNTIFS($B$2:B32,B32,$C$2:C32,C32,$D$2:D32,"<"&D32,$F$2:F32,1) -> 3 | P32: =IF(AND(R32=1,I32>0),1,IF(R32=1,-1,0)) -> 0 | Q32: =IF(I32>=$Z$1,"Monitor",IF(AND(N32>=$Z$2,L32<=-$Z$4),IF(O32<$Z$3,"Intervene","Escalate / Bigger Fix"),"Monitor")) -> Monitor | R32: 0 | S32: =IF(Q32="Intervene",1,IF(Q32="Escalate / Bigger Fix",-1,0)) -> 0 | T32: =IF(Q32="Intervene",1,0) -> 0 | U32: =IF(I32>=$Z$1,"Improved Enough","Not Improved Enough") -> Improved Enough | V32: =IF(N32>=$Z$2,"Far","Close") -> Far | W32: =IF(L32<=-$Z$4,"Abnormal","Normal") -> Normal | X32: =IF(O32<$Z$3,"Allowed","Maxed Out") -> Allowed
A33: Culture | B33: DH | C33: AES Metric 1 | D33: 45991 | E33: 0.063444109 | F33: 0 | G33: DOWN | H33: 0.054 | I33: -0.12398955 | J33: =AVERAGEIF($C:$C,C33,$I:$I) -> 0.010109679 | K33: {=_xlfn.STDEV.S(IF($C:$C=C33,$I:$I))} -> 0.17556417 | L33: =IFERROR((I33-J33)/K33,0) -> -0.76381889 | M33: =IF(L33<=-$Z$4,1,IF(L33>=$Z$4,-1,0)) -> 1 | N33: =IFERROR(IF(G33="DOWN",(E33-H33)/H33,(H33-E33)/H33),0) -> 0.1748909 | O33: =COUNTIFS($B$2:B33,B33,$C$2:C33,C33,$D$2:D33,"<"&D33,$F$2:F33,1) -> 3 | P33: =IF(AND(R33=1,I33>0),1,IF(R33=1,-1,0)) -> 0 | Q33: =IF(I33>=$Z$1,"Monitor",IF(AND(N33>=$Z$2,L33<=-$Z$4),IF(O33<$Z$3,"Intervene","Escalate / Bigger Fix"),"Monitor")) -> Intervene | R33: 0 | S33: =IF(Q33="Intervene",1,IF(Q33="Escalate / Bigger Fix",-1,0)) -> 1 | T33: =IF(Q33="Intervene",1,0) -> 1 | U33: =IF(I33>=$Z$1,"Improved Enough","Not Improved Enough") -> Not Improved Enough | V33: =IF(N33>=$Z$2,"Far","Close") -> Far | W33: =IF(L33<=-$Z$4,"Abnormal","Normal") -> Abnormal | X33: =IF(O33<$Z$3,"Allowed","Maxed Out") -> Allowed
... A1297: Service | B1297: RMH | C1297: Inpatient Metric 3 | D1297: 45991 | E1297: 0.733 | F1297: 0 | G1297: UP | H1297: 0.7 | I1297: -0.03298153 | J1297: =AVERAGEIF($C:$C,C1297,$I:$I) -> 0.019288788 | K1297: {=_xlfn.STDEV.S(IF($C:$C=C1297,$I:$I))} -> 0.27585789 | L1297: =IFERROR((I1297-J1297)/K1297,0) -> -0.18948277 | M1297: =IF(L1297<=-$Z$4,1,IF(L1297>=$Z$4,-1,0)) -> 0 | N1297: =IFERROR(IF(G1297="DOWN",(E1297-H1297)/H1297,(H1297-E1297)/H1297),0) -> -0.047142857 | O1297: =COUNTIFS($B$2:B1297,B1297,$C$2:C1297,C1297,$D$2:D1297,"<"&D1297,$F$2:F1297,1) -> 8 | P1297: =IF(AND(R1297=1,I1297>0),1,IF(R1297=1,-1,0)) -> 0 | Q1297: =IF(I1297>=$Z$1,"Monitor",IF(AND(N1297>=$Z$2,L1297<=-$Z$4),IF(O1297<$Z$3,"Intervene","Escalate / Bigger Fix"),"Monitor")) -> Monitor | R1297: 0 | S1297: =IF(Q1297="Intervene",1,IF(Q1297="Escalate / Bigger Fix",-1,0)) -> 0 | T1297: =IF(Q1297="Intervene",1,0) -> 0 | U1297: =IF(I1297>=$Z$1,"Improved Enough","Not Improved Enough") -> Not Improved Enough | V1297: =IF(N1297>=$Z$2,"Far","Close") -> Close | W1297: =IF(L1297<=-$Z$4,"Abnormal","Normal") -> Normal | X1297: =IF(O1297<$Z$3,"Allowed","Maxed Out") -> Maxed Out

Sheet Control panel
B9: Sum of Performance
C10: 45535 | D10: 45565 | E10: 45596 | F10: 45626 | G10: 45657 | H10: 45688 | I10: 45716 | J10: 45747 | K10: 45777 | L10: 45808 | M10: 45838 | N10: 45869 | O10: 45900 | P10: 45930 | Q10: 45961 | R10: 45991
B11: Culture | T11: Trend | U11: Target | W11: Heatmap Legend | AA11: Decision Control Panel
B12: 1st Year Voluntary Turnover | C12: 0.304 | D12: 0.30009872 | E12: 0.29296875 | F12: 0.29088559 | G12: 0.30193548 | H12: 0.30232558 | I12: 0.28859279 | J12: 0.27227886 | K12: 0.25540541 | L12: 0.25311203 | M12: 0.24929577 | N12: 0.24910523 | O12: 0.24534502 | P12: 0.25484352 | Q12: 0.2519084 | R12: 0.24394058 | T12: =_xlfn.XLOOKUP(B12,Data!C:C,Data!G:G,"") -> DOWN | U12: =_xlfn.XLOOKUP(B12,Data!C:C,Data!H:H,"") -> 0.27 | W12: Color | X12: Meaning | AA12: THRESHOLDS | AB12: SET THE THRESHOLDS | AC12: What it controls
B13: AES Metric 1 | C13: 0.078461538 | D13: 0.069821567 | E13: 0.071372549 | F13: 0.064414768 | G13: 0.065934066 | H13: 0.073265783 | I13: 0.080093313 | J13: 0.075617284 | K13: 0.088703563 | L13: 0.086956522 | M13: 0.075 | N13: 0.06981982 | O13: 0.067771084 | P13: 0.062878788 | Q13: 0.056445461 | R13: 0.063444109 | T13: =_xlfn.XLOOKUP(B13,Data!C:C,Data!G:G,"") -> DOWN | U13: =_xlfn.XLOOKUP(B13,Data!C:C,Data!H:H,"") -> 0.054 | W13: Green | X13: Meets or exceeds target | AA13: Improvement Threshold | AB13: 0.01 | AC13: Minimum improvement required to consider performance “good”
B14: AES Metric 2 | C14: 0.10755149 | D14: 0.11337868 | E14: 0.10189573 | F14: 0.083732057 | G14: 0.082938389 | H14: 0.099307159 | I14: 0.11187215 | J14: 0.095890411 | K14: 0.11607143 | L14: 0.096774194 | M14: 0.07816092 | N14: 0.075892857 | O14: 0.073991031 | P14: 0.077777778 | Q14: 0.057906459 | R14: 0.066225166 | T14: =_xlfn.XLOOKUP(B14,Data!C:C,Data!G:G,"") -> DOWN | U14: =_xlfn.XLOOKUP(B14,Data!C:C,Data!H:H,"") -> 0.066 | W14: Red | X14: Below target | AA14: Distance Threshold | AB14: 0.02 | AC14: How far from target triggers concern
B15: AES Metric 3 | C15: 0.15873016 | D15: 0.15625 | E15: 0.15625 | F15: 0.15873016 | G15: 0.16393443 | H15: 0.16129032 | I15: 0.16393443 | J15: 0.17741935 | K15: 0.17741935 | L15: 0.2 | M15: 0.2 | N15: 0.19672131 | O15: 0.203125 | P15: 0.20634921 | Q15: 0.20967742 | R15: 0.21875 | T15: =_xlfn.XLOOKUP(B15,Data!C:C,Data!G:G,"") -> UP | U15: =_xlfn.XLOOKUP(B15,Data!C:C,Data!H:H,"") -> 0.164 | AA15: Max Prior Interventions | AB15: 5 | AC15: Number of attempts before escalation
B16: AES Metric 5 | C16: 0.13279942 | D16: 0.13370957 | E16: 0.13289228 | F16: 0.13206603 | G16: 0.13562695 | H16: 0.13070231 | I16: 0.13101359 | J16: 0.12722932 | K16: 0.12201964 | L16: 0.11926092 | M16: 0.11891967 | N16: 0.11515194 | O16: 0.11812825 | P16: 0.11534472 | Q16: 0.10994764 | R16: 0.10966057 | T16: =_xlfn.XLOOKUP(B16,Data!C:C,Data!G:G,"") -> DOWN | U16: =_xlfn.XLOOKUP(B16,Data!C:C,Data!H:H,"") -> 0.104 | AA16: Z Threshold | AB16: 0.5 | AC16: Sensitivity to unusual changes
B17: AES Metric 6 | C17: 0.13849287 | D17: 0.15240642 | E17: 0.15737705 | F17: 0.15444015 | G17: 0.12870662 | H17: 0.11903286 | I17: 0.10995724 | J17: 0.10163339 | K17: 0.10836845 | L17: 0.10035842 | M17: 0.11245865 | N17: 0.10979329 | O17: 0.11740891 | P17: 0.10868836 | Q17: 0.095744681 | R17: 0.093859211 | T17: =_xlfn.XLOOKUP(B17,Data!C:C,Data!G:G,"") -> DOWN | U17: =_xlfn.XLOOKUP(B17,Data!C:C,Data!H:H,"") -> 0.1
B18: Quality | T18: =_xlfn.XLOOKUP(B18,Data!C:C,Data!G:G,"") | U18: =_xlfn.XLOOKUP(B18,Data!C:C,Data!H:H,"")
B19: CAUTI Metric 1 | C19: 0.458 | D19: 0.573 | E19: 0.63 | F19: 0.61 | G19: 0.59 | H19: 0.62 | I19: 0.61 | J19: 0.5 | K19: 0.56 | L19: 0.58 | M19: 0.57 | N19: 0.51 | O19: 0.48 | P19: 0.51 | Q19: 0.47 | T19: =_xlfn.XLOOKUP(B19,Data!C:C,Data!G:G,"") -> DOWN | U19: =_xlfn.XLOOKUP(B19,Data!C:C,Data!H:H,"") -> 0.59 | AA19: Threshold Guide
B20: CLABSI Metric 1 | C20: 0.652 | D20: 0.696 | E20: 0.824 | F20: 0.414 | G20: 0.75 | H20: 0.621 | I20: 0.727 | J20: 0.545 | K20: 0.767 | L20: 0.727 | M20: 0.867 | N20: 0.62 | O20: 0.66 | P20: 0.67 | Q20: 0.61 | T20: =_xlfn.XLOOKUP(B20,Data!C:C,Data!G:G,"") -> DOWN | U20: =_xlfn.XLOOKUP(B20,Data!C:C,Data!H:H,"") -> 0.57 | AA20: If you want | AB20: Adjust this
B21: Service | AA21: Fewer interventions | AB21: Increase all thresholds
B22: Emergency Metric 1 | C22: 0.7705 | D22: 0.8298 | E22: 0.8473 | F22: 0.8042 | G22: 0.7478 | H22: 0.7794 | I22: 0.8099 | J22: 0.8047 | K22: 0.8016 | L22: 0.7961 | M22: 0.8718 | N22: 0.827 | O22: 0.769 | P22: 0.878 | Q22: 0.794 | R22: 0.844 | T22: =_xlfn.XLOOKUP(B22,Data!C:C,Data!G:G,"") -> UP | U22: =_xlfn.XLOOKUP(B22,Data!C:C,Data!H:H,"") -> 0.85 | AA22: Catch issues early | AB22: Lower Distance & Z
B23: Inpatient Metric 1 | C23: 0.68 | D23: 0.7238 | E23: 0.7 | F23: 0.6842 | G23: 0.71 | H23: 0.65 | I23: 0.7444 | J23: 0.8137 | K23: 0.6356 | L23: 0.7155 | M23: 0.7065 | N23: 0.771 | O23: 0.698 | P23: 0.733 | Q23: 0.839 | R23: 0.7324 | T23: =_xlfn.XLOOKUP(B23,Data!C:C,Data!G:G,"") -> UP | U23: =_xlfn.XLOOKUP(B23,Data!C:C,Data!H:H,"") -> 0.65 | AA23: Reduce noise | AB23: Increase Improvement
B24: Inpatient Metric 2 | C24: 0.8712 | D24: 0.8679 | E24: 0.8519 | F24: 0.7866 | G24: 0.9118 | H24: 0.8306 | I24: 0.875 | J24: 0.8431 | K24: 0.8559 | L24: 0.8426 | M24: 0.9341 | N24: 0.853 | O24: 0.902 | P24: 0.808 | Q24: 0.895 | R24: 0.909 | T24: =_xlfn.XLOOKUP(B24,Data!C:C,Data!G:G,"") -> UP | U24: =_xlfn.XLOOKUP(B24,Data!C:C,Data!H:H,"") -> 0.85 | AA24: Escalate faster | AB24: Lower Max Interventions
B25: Inpatient Metric 3 | C25: 0.8416 | D25: 0.8235 | E25: 0.8272 | F25: 0.7867 | G25: 0.8469 | H25: 0.8667 | I25: 0.8864 | J25: 0.87 | K25: 0.7647 | L25: 0.7981 | M25: 0.809 | N25: 0.844 | O25: 0.842 | P25: 0.845 | Q25: 0.805 | R25: 0.821 | T25: =_xlfn.XLOOKUP(B25,Data!C:C,Data!G:G,"") -> UP | U25: =_xlfn.XLOOKUP(B25,Data!C:C,Data!H:H,"") -> 0.7
B30: Max of Decision_Code | W30: Decision Heatmap - Legend | AA30: Metrics | AB30: New Interventions | AC30: Old Interventions
C31: 45535 | D31: 45565 | E31: 45596 | F31: 45626 | G31: 45657 | H31: 45688 | I31: 45716 | J31: 45747 | K31: 45777 | L31: 45808 | M31: 45838 | N31: 45869 | O31: 45900 | P31: 45930 | Q31: 45961 | R31: 45991 | T31: Trend | U31: Target | W31: Value | X31: Meaning | Y31: Color | AA31: 1st Year Voluntary Turnover | AB31: 1 | AC31: 3
B32: Culture | T32: =_xlfn.XLOOKUP(B32,Data!C:C,Data!G:G,"") | W32: 1 | X32: Intervention / Action Taken | Y32: Red | AA32: AES Metric 1 | AB32: 4 | AC32: 3
B33: 1st Year Voluntary Turnover | C33: 0 | D33: 0 | E33: 0 | F33: 0 | G33: 1 | H33: 0 | I33: 0 | J33: 0 | K33: 0 | L33: 0 | M33: 0 | N33: 0 | O33: 0 | P33: 0 | Q33: 0 | R33: 0 | T33: =_xlfn.XLOOKUP(B33,Data!C:C,Data!G:G,"") -> DOWN | U33: =_xlfn.XLOOKUP(B33,Data!C:C,Data!H:H,"") -> 0.27 | W33: 0 | X33: Monitor / No Action Needed | Y33: Green | AA33: AES Metric 2 | AB33: 0 | AC33: 6
B34: AES Metric 1 | C34: 0 | D34: 0 | E34: 0 | F34: 0 | G34: 0 | H34: 1 | I34: 1 | J34: 0 | K34: 1 | L34: 0 | M34: 0 | N34: 0 | O34: 0 | P34: 0 | Q34: 0 | R34: 1 | T34: =_xlfn.XLOOKUP(B34,Data!C:C,Data!G:G,"") -> DOWN | U34: =_xlfn.XLOOKUP(B34,Data!C:C,Data!H:H,"") -> 0.054 | W34: -1 | X34: Escalate / Bigger Fix Needed | Y34: Orange | AA34: AES Metric 3 | AB34: 0 | AC34: 0
B35: AES Metric 2 | C35: 0 | D35: 0 | E35: 0 | F35: 0 | G35: 0 | H35: 0 | I35: 0 | J35: 0 | K35: 0 | L35: 0 | M35: 0 | N35: 0 | O35: 0 | P35: 0 | Q35: 0 | R35: 0 | T35: =_xlfn.XLOOKUP(B35,Data!C:C,Data!G:G,"") -> DOWN | U35: =_xlfn.XLOOKUP(B35,Data!C:C,Data!H:H,"") -> 0.066 | AA35: AES Metric 5 | AB35: 0 | AC35: 4
B36: AES Metric 3 | C36: 0 | D36: 0 | E36: 0 | F36: 0 | G36: 0 | H36: 0 | I36: 0 | J36: 0 | K36: 0 | L36: 0 | M36: 0 | N36: 0 | O36: 0 | P36: 0 | Q36: 0 | R36: 0 | T36: =_xlfn.XLOOKUP(B36,Data!C:C,Data!G:G,"") -> UP | U36: =_xlfn.XLOOKUP(B36,Data!C:C,Data!H:H,"") -> 0.164 | AA36: AES Metric 6 | AB36: 2 | AC36: 2
B37: AES Metric 5 | C37: 0 | D37: 0 | E37: 0 | F37: 0 | G37: 0 | H37: 0 | I37: 0 | J37: 0 | K37: 0 | L37: 0 | M37: 0 | N37: 0 | O37: 0 | P37: 0 | Q37: 0 | R37: 0 | T37: =_xlfn.XLOOKUP(B37,Data!C:C,Data!G:G,"") -> DOWN | U37: =_xlfn.XLOOKUP(B37,Data!C:C,Data!H:H,"") -> 0.104 | AA37: CAUTI Metric 1 | AB37: 0 | AC37: 0
B38: AES Metric 6 | C38: 0 | D38: 1 | E38: 0 | F38: 0 | G38: 0 | H38: 0 | I38: 0 | J38: 0 | K38: 0 | L38: 0 | M38: 1 | N38: 0 | O38: 0 | P38: 0 | Q38: 0 | R38: 0 | T38: =_xlfn.XLOOKUP(B38,Data!C:C,Data!G:G,"") -> DOWN | U38: =_xlfn.XLOOKUP(B38,Data!C:C,Data!H:H,"") -> 0.1 | AA38: CLABSI Metric 1 | AB38: 2 | AC38: 6
B39: Quality | T39: =_xlfn.XLOOKUP(B39,Data!C:C,Data!G:G,"") | U39: =_xlfn.XLOOKUP(B39,Data!C:C,Data!H:H,"") | AA39: Emergency Metric 1 | AB39: 2 | AC39: 7
B40: CAUTI Metric 1 | C40: 0 | D40: 0 | E40: 0 | F40: 0 | G40: 0 | H40: 0 | I40: 0 | J40: 0 | K40: 0 | L40: 0 | M40: 0 | N40: 0 | O40: 0 | P40: 0 | Q40: 0 | T40: =_xlfn.XLOOKUP(B40,Data!C:C,Data!G:G,"") -> DOWN | U40: =_xlfn.XLOOKUP(B40,Data!C:C,Data!H:H,"") -> 0.59 | AA40: Inpatient Metric 1 | AB40: 1 | AC40: 0
B41: CLABSI Metric 1 | C41: 0 | D41: 0 | E41: 0 | F41: 0 | G41: 1 | H41: 0 | I41: 0 | J41: 0 | K41: 1 | L41: 0 | M41: 0 | N41: 0 | O41: 0 | P41: 0 | Q41: 0 | T41: =_xlfn.XLOOKUP(B41,Data!C:C,Data!G:G,"") -> DOWN | U41: =_xlfn.XLOOKUP(B41,Data!C:C,Data!H:H,"") -> 0.57 | AA41: Inpatient Metric 2 | AB41: 1 | AC41: 0
B42: Service | U42: =_xlfn.XLOOKUP(B42,Data!C:C,Data!H:H,"") | AA42: Inpatient Metric 3 | AB42: 0 | AC42: 0
B43: Emergency Metric 1 | C43: 0 | D43: 0 | E43: 0 | F43: 1 | G43: 1 | H43: 0 | I43: 0 | J43: 0 | K43: 0 | L43: 0 | M43: 0 | N43: -1 | O43: -1 | P43: 0 | Q43: -1 | R43: 0 | T43: =_xlfn.XLOOKUP(B43,Data!C:C,Data!G:G,"") -> UP | U43: =_xlfn.XLOOKUP(B43,Data!C:C,Data!H:H,"") -> 0.85 | AA43: Grand Total | AB43: 13 | AC43: 31
B44: Inpatient Metric 1 | C44: 0 | D44: 0 | E44: 0 | F44: 0 | G44: 0 | H44: 0 | I44: 0 | J44: 0 | K44: 1 | L44: 0 | M44: 0 | N44: 0 | O44: 0 | P44: 0 | Q44: 0 | R44: 0 | T44: =_xlfn.XLOOKUP(B44,Data!C:C,Data!G:G,"") -> UP | U44: =_xlfn.XLOOKUP(B44,Data!C:C,Data!H:H,"") -> 0.65
B45: Inpatient Metric 2 | C45: 0 | D45: 0 | E45: 0 | F45: 0 | G45: 0 | H45: 0 | I45: 0 | J45: 0 | K45: 0 | L45: 0 | M45: 0 | N45: 0 | O45: 0 | P45: 1 | Q45: 0 | R45: 0 | T45: =_xlfn.XLOOKUP(B45,Data!C:C,Data!G:G,"") -> UP | U45: =_xlfn.XLOOKUP(B45,Data!C:C,Data!H:H,"") -> 0.85
B46: Inpatient Metric 3 | C46: 0 | D46: 0 | E46: 0 | F46: 0 | G46: 0 | H46: 0 | I46: 0 | J46: 0 | K46: 0 | L46: 0 | M46: 0 | N46: 0 | O46: 0 | P46: 0 | Q46: 0 | R46: 0 | T46: =_xlfn.XLOOKUP(B46,Data!C:C,Data!G:G,"") -> UP | U46: =_xlfn.XLOOKUP(B46,Data!C:C,Data!H:H,"") -> 0.7

Sheet KPI
C3: 1. Decision Distribution | J3: 5. Interventions by Metric( New Interventions vs Old Interventions)
C4: Decision | D4: Count of Decision | J4: Metrics | K4: Sum of New_Intervention | L4: Sum of intervention
C5: Escalate / Bigger Fix | D5: 3 | J5: 1st Year Voluntary Turnover | K5: 1 | L5: 3
C6: Intervene | D6: 13 | J6: AES Metric 1 | K6: 4 | L6: 3
C7: Monitor | D7: 174 | J7: AES Metric 2 | K7: 0 | L7: 6
C8: Grand Total | D8: 190 | J8: AES Metric 3 | K8: 0 | L8: 0
J9: AES Metric 5 | K9: 0 | L9: 4
C10: 2. Intervention vs Improvement Outcome | J10: AES Metric 6 | K10: 2 | L10: 2
C11: Count of Improvement_Check | D11: Column Labels | J11: CAUTI Metric 1 | K11: 0 | L11: 0
C12: Decision | D12: Improved Enough | E12: Not Improved Enough | F12: Grand Total | J12: CLABSI Metric 1 | K12: 2 | L12: 6
C13: Escalate / Bigger Fix | E13: 3 | F13: 3 | J13: Emergency Metric 1 | K13: 2 | L13: 7
C14: Intervene | E14: 13 | F14: 13 | J14: Inpatient Metric 1 | K14: 1 | L14: 0
C15: Monitor | D15: 100 | E15: 74 | F15: 174 | J15: Inpatient Metric 2 | K15: 1 | L15: 0
C16: Grand Total | D16: 100 | E16: 90 | F16: 190 | J16: Inpatient Metric 3 | K16: 0 | L16: 0
J17: Grand Total | K17: 13 | L17: 31
C19: 3. Top Risk Metrics(Distance-based)
C20: Metrics | D20: Average of Distance_from_Target | J20: 6. Distance from Target vs Improvement Outcome
C21: AES Metric 2 | D21: 0.36303589 | J21: Distance | K21: Improvement
C22: AES Metric 1 | D22: 0.33101877 | J22: Row Labels | K22: Improved Enough | L22: Not Improved Enough | M22: Grand Total
C23: AES Metric 6 | D23: 0.19295412 | J23: Close | K23: 54 | L23: 34 | M23: 88 | N23: If Far + Not Improving is high - keep distance threshold strict
C24: AES Metric 5 | D24: 0.19259185 | J24: Far | K24: 46 | L24: 56 | M24: 102 | N24: If Far + Improving is high - threshold too aggressive
C25: CLABSI Metric 1 | D25: 0.1871345 | J25: Grand Total | K25: 100 | L25: 90 | M25: 190
C26: Emergency Metric 1 | D26: 0.045948529
C27: 1st Year Voluntary Turnover | D27: 0.0083429874
C28: Inpatient Metric 2 | D28: -0.017477941 | J28: 7. Observed Performance Change by Action Type
C29: CAUTI Metric 1 | D29: -0.065423729 | J29: Decision | K29: Average of pct_change
C30: AES Metric 3 | D30: -0.10845318 | J30: Escalate / Bigger Fix | K30: -0.072397642
C31: Inpatient Metric 1 | D31: -0.10933654 | J31: Intervene | K31: -0.18642145
C32: Inpatient Metric 3 | D32: -0.18551786 | J32: Monitor | K32: 0.021688129
C33: Grand Total | D33: 0.06965983 | J33: Grand Total | K33: 0.0059634879
C35: 4. Site Comparison
C36: Site | D36: Sum of New_Intervention | E36: Sum of intervention | F36: Average of Distance_from_Target
C37: DH | D37: 13 | E37: 31 | F37: 0.06965983

Sheet README
A1: OhioHealth Control Panel - User Guide
A3: Purpose
A5: This tool helps identify when performance changes require action and when variation is likely normal.
A7: It improves decision-making by distinguishing between:
A9: normal variation (monitor)
A10: meaningful decline (intervene)
A11: repeated unresolved issues (escalate)
A13: The goal is to reduce unnecessary interventions and focus effort on high-priority issues.
A17: Decision Definitions
A19: Monitor
A21: Performance variation appears normal.
A22: No immediate action is needed. Continue observing future periods.
... A155: This workbook is built for structured monthly updates and works best when the source format remains consistent.

Sheet Read PCT_CHANGE
A1: Quadrant | B1: Site | C1: metric_std | D1: Date | E1: Performance | F1: intervention | G1: Ideal_Trend | H1: Target | I1: PCT_CHANGE
A2: Culture | B2: DH | C2: 1st Year Voluntary Turnover | D2: 45535 | E2: 0.304 | F2: 0 | G2: DOWN | H2: 0.27 | N2: What this tab does
A3: Culture | B3: DH | C3: 1st Year Voluntary Turnover | D3: 45565 | E3: 0.30009872 | F3: 1 | G3: DOWN | H3: 0.27 | I3: =IF(OR(B3<>B2,C3<>C2),"",IF(E2=0,"",IF(G3="UP",(E3-E2)/E2,-((E3-E2)/E2)))) -> 0.012833169
A4: Culture | B4: DH | C4: 1st Year Voluntary Turnover | D4: 45596 | E4: 0.29296875 | F4: 0 | G4: DOWN | H4: 0.27 | I4: =IF(OR(B4<>B3,C4<>C3),"",IF(E3=0,"",IF(G4="UP",(E4-E3)/E3,-((E4-E3)/E3)))) -> 0.023758738 | N4: Converts raw monthly performance into normalized percent change.
A5: Culture | B5: DH | C5: 1st Year Voluntary Turnover | D5: 45626 | E5: 0.29088559 | F5: 0 | G5: DOWN | H5: 0.27 | I5: =IF(OR(B5<>B4,C5<>C4),"",IF(E4=0,"",IF(G5="UP",(E5-E4)/E4,-((E5-E4)/E4)))) -> 0.0071105365
A6: Culture | B6: DH | C6: 1st Year Voluntary Turnover | D6: 45657 | E6: 0.30193548 | F6: 1 | G6: DOWN | H6: 0.27 | I6: =IF(OR(B6<>B5,C6<>C5),"",IF(E5=0,"",IF(G6="UP",(E6-E5)/E5,-((E6-E5)/E5)))) -> -0.037987097 | N6: This standardizes all metrics so they can be interpreted consistently across the control panel.
A7: Culture | B7: DH | C7: 1st Year Voluntary Turnover | D7: 45688 | E7: 0.30232558 | F7: 1 | G7: DOWN | H7: 0.27 | I7: =IF(OR(B7<>B6,C7<>C6),"",IF(E6=0,"",IF(G7="UP",(E7-E6)/E6,-((E7-E6)/E6)))) -> -0.0012919897
A8: Culture | B8: DH | C8: 1st Year Voluntary Turnover | D8: 45716 | E8: 0.28859279 | F8: 0 | G8: DOWN | H8: 0.27 | I8: =IF(OR(B8<>B7,C8<>C7),"",IF(E7=0,"",IF(G8="UP",(E8-E7)/E7,-((E8-E7)/E7)))) -> 0.045423864 | N8: How PCT_CHANGE works
A9: Culture | B9: DH | C9: 1st Year Voluntary Turnover | D9: 45747 | E9: 0.27227886 | F9: 0 | G9: DOWN | H9: 0.27 | I9: =IF(OR(B9<>B8,C9<>C8),"",IF(E8=0,"",IF(G9="UP",(E9-E8)/E8,-((E9-E8)/E8)))) -> 0.056529236
A10: Culture | B10: DH | C10: 1st Year Voluntary Turnover | D10: 45777 | E10: 0.25540541 | F10: 0 | G10: DOWN | H10: 0.27 | I10: =IF(OR(B10<>B9,C10<>C9),"",IF(E9=0,"",IF(G10="UP",(E10-E9)/E9,-((E10-E9)/E9)))) -> 0.06197121 | N10: PCT_CHANGE compares the current month to the prior month and adjusts direction based on Ideal Trend.
A11: Culture | B11: DH | C11: 1st Year Voluntary Turnover | D11: 45808 | E11: 0.25311203 | F11: 0 | G11: DOWN | H11: 0.27 | I11: =IF(OR(B11<>B10,C11<>C10),"",IF(E10=0,"",IF(G11="UP",(E11-E10)/E10,-((E11-E10)/E10)))) -> 0.0089793409
A12: Culture | B12: DH | C12: 1st Year Voluntary Turnover | D12: 45838 | E12: 0.24929577 | F12: 0 | G12: DOWN | H12: 0.27 | I12: =IF(OR(B12<>B11,C12<>C11),"",IF(E11=0,"",IF(G12="UP",(E12-E11)/E11,-((E12-E11)/E11)))) -> 0.015077349 | N12: Positive value = performance improved
A13: Culture | B13: DH | C13: 1st Year Voluntary Turnover | D13: 45869 | E13: 0.24910523 | F13: 0 | G13: DOWN | H13: 0.27 | I13: =IF(OR(B13<>B12,C13<>C12),"",IF(E12=0,"",IF(G13="UP",(E13-E12)/E12,-((E13-E12)/E12)))) -> 0.00076434976 | N13: Negative value = performance declined
A14: Culture | B14: DH | C14: 1st Year Voluntary Turnover | D14: 45900 | E14: 0.24534502 | F14: 0 | G14: DOWN | H14: 0.27 | I14: =IF(OR(B14<>B13,C14<>C13),"",IF(E13=0,"",IF(G14="UP",(E14-E13)/E13,-((E14-E13)/E13)))) -> 0.015094862 | N14: 0 = no meaningful change
A15: Culture | B15: DH | C15: 1st Year Voluntary Turnover | D15: 45930 | E15: 0.25484352 | F15: 0 | G15: DOWN | H15: 0.27 | I15: =IF(OR(B15<>B14,C15<>C14),"",IF(E14=0,"",IF(G15="UP",(E15-E14)/E14,-((E15-E14)/E14)))) -> -0.038714871
A16: Culture | B16: DH | C16: 1st Year Voluntary Turnover | D16: 45961 | E16: 0.2519084 | F16: 0 | G16: DOWN | H16: 0.27 | I16: =IF(OR(B16<>B15,C16<>C15),"",IF(E15=0,"",IF(G16="UP",(E16-E15)/E15,-((E16-E15)/E15)))) -> 0.011517343 | N16: This rule is standardized across all metrics.
A17: Culture | B17: DH | C17: 1st Year Voluntary Turnover | D17: 45991 | E17: 0.24394058 | F17: 0 | G17: DOWN | H17: 0.27 | I17: =IF(OR(B17<>B16,C17<>C16),"",IF(E16=0,"",IF(G17="UP",(E17-E16)/E16,-((E17-E16)/E16)))) -> 0.031629824
A18: Culture | B18: DH | C18: AES Metric 1 | D18: 45535 | E18: 0.078461538 | F18: 0 | G18: DOWN | H18: 0.054 | I18: =IF(OR(B18<>B17,C18<>C17),"",IF(E17=0,"",IF(G18="UP",(E18-E17)/E17,-((E18-E17)/E17))))
A19: Culture | B19: DH | C19: AES Metric 1 | D19: 45565 | E19: 0.069821567 | F19: 0 | G19: DOWN | H19: 0.054 | I19: =IF(OR(B19<>B18,C19<>C18),"",IF(E18=0,"",IF(G19="UP",(E19-E18)/E18,-((E19-E18)/E18)))) -> 0.11011728 | N19: How trend affects interpretation
A20: Culture | B20: DH | C20: AES Metric 1 | D20: 45596 | E20: 0.071372549 | F20: 0 | G20: DOWN | H20: 0.054 | I20: =IF(OR(B20<>B19,C20<>C19),"",IF(E19=0,"",IF(G20="UP",(E20-E19)/E19,-((E20-E19)/E19)))) -> -0.022213508
A21: Culture | B21: DH | C21: AES Metric 1 | D21: 45626 | E21: 0.064414768 | F21: 0 | G21: DOWN | H21: 0.054 | I21: =IF(OR(B21<>B20,C21<>C20),"",IF(E20=0,"",IF(G21="UP",(E21-E20)/E20,-((E21-E20)/E20)))) -> 0.097485393 | N21: UP metrics
A22: Culture | B22: DH | C22: AES Metric 1 | D22: 45657 | E22: 0.065934066 | F22: 1 | G22: DOWN | H22: 0.054 | I22: =IF(OR(B22<>B21,C22<>C21),"",IF(E21=0,"",IF(G22="UP",(E22-E21)/E21,-((E22-E21)/E21)))) -> -0.023586174
A23: Culture | B23: DH | C23: AES Metric 1 | D23: 45688 | E23: 0.073265783 | F23: 1 | G23: DOWN | H23: 0.054 | I23: =IF(OR(B23<>B22,C23<>C22),"",IF(E22=0,"",IF(G23="UP",(E23-E22)/E22,-((E23-E22)/E22)))) -> -0.11119771 | N23: Higher values are better
A24: Culture | B24: DH | C24: AES Metric 1 | D24: 45716 | E24: 0.080093313 | F24: 1 | G24: DOWN | H24: 0.054 | I24: =IF(OR(B24<>B23,C24<>C23),"",IF(E23=0,"",IF(G24="UP",(E24-E23)/E23,-((E24-E23)/E23)))) -> -0.093188511 | N24: Example: 0.70 -> 0.75 = improvement
A25: Culture | B25: DH | C25: AES Metric 1 | D25: 45747 | E25: 0.075617284 | F25: 0 | G25: DOWN | H25: 0.054 | I25: =IF(OR(B25<>B24,C25<>C24),"",IF(E24=0,"",IF(G25="UP",(E25-E24)/E24,-((E25-E24)/E24)))) -> 0.055885173
A26: Culture | B26: DH | C26: AES Metric 1 | D26: 45777 | E26: 0.088703563 | F26: 0 | G26: DOWN | H26: 0.054 | I26: =IF(OR(B26<>B25,C26<>C25),"",IF(E25=0,"",IF(G26="UP",(E26-E25)/E25,-((E26-E25)/E25)))) -> -0.17305937 | N26: DOWN metrics
A27: Culture | B27: DH | C27: AES Metric 1 | D27: 45808 | E27: 0.086956522 | F27: 0 | G27: DOWN | H27: 0.054 | I27: =IF(OR(B27<>B26,C27<>C26),"",IF(E26=0,"",IF(G27="UP",(E27-E26)/E26,-((E27-E26)/E26)))) -> 0.019695281
A28: Culture | B28: DH | C28: AES Metric 1 | D28: 45838 | E28: 0.075 | F28: 0 | G28: DOWN | H28: 0.054 | I28: =IF(OR(B28<>B27,C28<>C27),"",IF(E27=0,"",IF(G28="UP",(E28-E27)/E27,-((E28-E27)/E27)))) -> 0.1375 | N28: Lower values are better
A29: Culture | B29: DH | C29: AES Metric 1 | D29: 45869 | E29: 0.06981982 | F29: 0 | G29: DOWN | H29: 0.054 | I29: =IF(OR(B29<>B28,C29<>C28),"",IF(E28=0,"",IF(G29="UP",(E29-E28)/E28,-((E29-E28)/E28)))) -> 0.069069069 | N29: Example: 0.30 -> 0.27 = improvement
A30: Culture | B30: DH | C30: AES Metric 1 | D30: 45900 | E30: 0.067771084 | F30: 0 | G30: DOWN | H30: 0.054 | I30: =IF(OR(B30<>B29,C30<>C29),"",IF(E29=0,"",IF(G30="UP",(E30-E29)/E29,-((E30-E29)/E29)))) -> 0.029343179
A31: Culture | B31: DH | C31: AES Metric 1 | D31: 45930 | E31: 0.062878788 | F31: 0 | G31: DOWN | H31: 0.054 | I31: =IF(OR(B31<>B30,C31<>C30),"",IF(E30=0,"",IF(G31="UP",(E31-E30)/E30,-((E31-E30)/E30)))) -> 0.072188552 | N31: To keep interpretation consistent, DOWN metrics are direction-adjusted so improvement is still positive.
A32: Culture | B32: DH | C32: AES Metric 1 | D32: 45961 | E32: 0.056445461 | F32: 0 | G32: DOWN | H32: 0.054 | I32: =IF(OR(B32<>B31,C32<>C31),"",IF(E31=0,"",IF(G32="UP",(E32-E31)/E31,-((E32-E31)/E31)))) -> 0.10231314
A33: Culture | B33: DH | C33: AES Metric 1 | D33: 45991 | E33: 0.063444109 | F33: 0 | G33: DOWN | H33: 0.054 | I33: =IF(OR(B33<>B32,C33<>C32),"",IF(E32=0,"",IF(G33="UP",(E33-E32)/E32,-((E33-E32)/E32)))) -> -0.12398955
A34: Culture | B34: DH | C34: AES Metric 2 | D34: 45535 | E34: 0.10755149 | F34: 1 | G34: DOWN | H34: 0.066 | I34: =IF(OR(B34<>B33,C34<>C33),"",IF(E33=0,"",IF(G34="UP",(E34-E33)/E33,-((E34-E33)/E33))))
A35: Culture | B35: DH | C35: AES Metric 2 | D35: 45565 | E35: 0.11337868 | F35: 1 | G35: DOWN | H35: 0.066 | I35: =IF(OR(B35<>B34,C35<>C34),"",IF(E34=0,"",IF(G35="UP",(E35-E34)/E34,-((E35-E34)/E34)))) -> -0.054180537
A36: Culture | B36: DH | C36: AES Metric 2 | D36: 45596 | E36: 0.10189573 | F36: 1 | G36: DOWN | H36: 0.066 | I36: =IF(OR(B36<>B35,C36<>C35),"",IF(E35=0,"",IF(G36="UP",(E36-E35)/E35,-((E36-E35)/E35)))) -> 0.10127962
A37: Culture | B37: DH | C37: AES Metric 2 | D37: 45626 | E37: 0.083732057 | F37: 0 | G37: DOWN | H37: 0.066 | I37: =IF(OR(B37<>B36,C37<>C36),"",IF(E36=0,"",IF(G37="UP",(E37-E36)/E36,-((E37-E36)/E36)))) -> 0.17825749
A38: Culture | B38: DH | C38: AES Metric 2 | D38: 45657 | E38: 0.082938389 | F38: 0 | G38: DOWN | H38: 0.066 | I38: =IF(OR(B38<>B37,C38<>C37),"",IF(E37=0,"",IF(G38="UP",(E38-E37)/E37,-((E38-E37)/E37)))) -> 0.0094786681
A39: Culture | B39: DH | C39: AES Metric 2 | D39: 45688 | E39: 0.099307159 | F39: 1 | G39: DOWN | H39: 0.066 | I39: =IF(OR(B39<>B38,C39<>C38),"",IF(E38=0,"",IF(G39="UP",(E39-E38)/E38,-((E39-E38)/E38)))) -> -0.19736061
A40: Culture | B40: DH | C40: AES Metric 2 | D40: 45716 | E40: 0.11187215 | F40: 1 | G40: DOWN | H40: 0.066 | I40: =IF(OR(B40<>B39,C40<>C39),"",IF(E39=0,"",IF(G40="UP",(E40-E39)/E39,-((E40-E39)/E39)))) -> -0.12652649
...
